<?xml version="1.0" encoding="UTF-8"?>
<testng-results skipped="0" failed="1" ignored="0" total="2" passed="1">
  <reporter-output>
  </reporter-output>
  <suite name="TestNgPOM Selenium Easy Test Suite" duration-ms="1320" started-at="2021-03-25T07:27:37Z" finished-at="2021-03-25T07:27:38Z">
    <groups>
    </groups>
    <test name="Selenium Easy Test Site Test Cases" duration-ms="1320" started-at="2021-03-25T07:27:37Z" finished-at="2021-03-25T07:27:38Z">
      <class name="com.qa.testcases.DummyTestClass1">
        <test-method status="PASS" signature="setUp()[pri:0, instance:com.qa.testcases.DummyTestClass1@4cf777e8]" name="setUp" is-config="true" duration-ms="9656" started-at="2021-03-25T07:27:27Z" finished-at="2021-03-25T07:27:37Z">
          <reporter-output>
          </reporter-output>
        </test-method> <!-- setUp -->
        <test-method status="FAIL" signature="dummyOne_FailTest()[pri:1, instance:com.qa.testcases.DummyTestClass1@4cf777e8]" name="dummyOne_FailTest" duration-ms="11" started-at="2021-03-25T07:27:37Z" finished-at="2021-03-25T07:27:37Z">
          <exception class="java.lang.AssertionError">
            <message>
              <![CDATA[expected [expected] but found [actual]]]>
            </message>
            <full-stacktrace>
              <![CDATA[java.lang.AssertionError: expected [expected] but found [actual]
at org.testng.Assert.fail(Assert.java:96)
at com.qa.util.Asserter.assertValues(Asserter.java:25)
at com.qa.testcases.DummyTestClass1.dummyOne_FailTest(DummyTestClass1.java:24)
at sun.reflect.NativeMethodAccessorImpl.invoke0(Native Method)
at sun.reflect.NativeMethodAccessorImpl.invoke(NativeMethodAccessorImpl.java:62)
at sun.reflect.DelegatingMethodAccessorImpl.invoke(DelegatingMethodAccessorImpl.java:43)
at java.lang.reflect.Method.invoke(Method.java:498)
at org.testng.internal.MethodInvocationHelper.invokeMethod(MethodInvocationHelper.java:124)
at org.testng.internal.Invoker.invokeMethod(Invoker.java:583)
at org.testng.internal.Invoker.invokeTestMethod(Invoker.java:719)
at org.testng.internal.Invoker.invokeTestMethods(Invoker.java:989)
at org.testng.internal.TestMethodWorker.invokeTestMethods(TestMethodWorker.java:125)
at org.testng.internal.TestMethodWorker.run(TestMethodWorker.java:109)
at org.testng.TestRunner.privateRun(TestRunner.java:648)
at org.testng.TestRunner.run(TestRunner.java:505)
at org.testng.SuiteRunner.runTest(SuiteRunner.java:455)
at org.testng.SuiteRunner.runSequentially(SuiteRunner.java:450)
at org.testng.SuiteRunner.privateRun(SuiteRunner.java:415)
at org.testng.SuiteRunner.run(SuiteRunner.java:364)
at org.testng.SuiteRunnerWorker.runSuite(SuiteRunnerWorker.java:52)
at org.testng.SuiteRunnerWorker.run(SuiteRunnerWorker.java:84)
at org.testng.TestNG.runSuitesSequentially(TestNG.java:1208)
at org.testng.TestNG.runSuitesLocally(TestNG.java:1137)
at org.testng.TestNG.runSuites(TestNG.java:1049)
at org.testng.TestNG.run(TestNG.java:1017)
at org.testng.remote.AbstractRemoteTestNG.run(AbstractRemoteTestNG.java:115)
at org.testng.remote.RemoteTestNG.initAndRun(RemoteTestNG.java:251)
at org.testng.remote.RemoteTestNG.main(RemoteTestNG.java:77)
]]>
            </full-stacktrace>
          </exception> <!-- java.lang.AssertionError -->
          <reporter-output>
          </reporter-output>
        </test-method> <!-- dummyOne_FailTest -->
        <test-method status="PASS" signature="assertAll()[pri:0, instance:com.qa.testcases.DummyTestClass1@4cf777e8]" name="assertAll" is-config="true" duration-ms="0" started-at="2021-03-25T07:27:38Z" finished-at="2021-03-25T07:27:38Z">
          <reporter-output>
          </reporter-output>
        </test-method> <!-- assertAll -->
        <test-method status="PASS" signature="dummyOne_PassTest()[pri:2, instance:com.qa.testcases.DummyTestClass1@4cf777e8]" name="dummyOne_PassTest" duration-ms="3" started-at="2021-03-25T07:27:38Z" finished-at="2021-03-25T07:27:38Z">
          <reporter-output>
          </reporter-output>
        </test-method> <!-- dummyOne_PassTest -->
        <test-method status="FAIL" signature="assertAll()[pri:0, instance:com.qa.testcases.DummyTestClass1@4cf777e8]" name="assertAll" is-config="true" duration-ms="0" started-at="2021-03-25T07:27:38Z" finished-at="2021-03-25T07:27:38Z">
          <exception class="java.lang.AssertionError">
            <message>
              <![CDATA[The following asserts failed:
expected [Assert] but found [Soft]]]>
            </message>
            <full-stacktrace>
              <![CDATA[java.lang.AssertionError: The following asserts failed:
expected [Assert] but found [Soft]
at org.testng.asserts.SoftAssert.assertAll(SoftAssert.java:43)
at com.qa.util.Asserter.assertAll(Asserter.java:32)
at com.qa.testcases.DummyTestClass1.assertAll(DummyTestClass1.java:19)
at sun.reflect.NativeMethodAccessorImpl.invoke0(Native Method)
at sun.reflect.NativeMethodAccessorImpl.invoke(NativeMethodAccessorImpl.java:62)
at sun.reflect.DelegatingMethodAccessorImpl.invoke(DelegatingMethodAccessorImpl.java:43)
at java.lang.reflect.Method.invoke(Method.java:498)
at org.testng.internal.MethodInvocationHelper.invokeMethod(MethodInvocationHelper.java:124)
at org.testng.internal.MethodInvocationHelper.invokeMethodConsideringTimeout(MethodInvocationHelper.java:59)
at org.testng.internal.Invoker.invokeConfigurationMethod(Invoker.java:458)
at org.testng.internal.Invoker.invokeConfigurations(Invoker.java:222)
at org.testng.internal.Invoker.invokeMethod(Invoker.java:646)
at org.testng.internal.Invoker.invokeTestMethod(Invoker.java:719)
at org.testng.internal.Invoker.invokeTestMethods(Invoker.java:989)
at org.testng.internal.TestMethodWorker.invokeTestMethods(TestMethodWorker.java:125)
at org.testng.internal.TestMethodWorker.run(TestMethodWorker.java:109)
at org.testng.TestRunner.privateRun(TestRunner.java:648)
at org.testng.TestRunner.run(TestRunner.java:505)
at org.testng.SuiteRunner.runTest(SuiteRunner.java:455)
at org.testng.SuiteRunner.runSequentially(SuiteRunner.java:450)
at org.testng.SuiteRunner.privateRun(SuiteRunner.java:415)
at org.testng.SuiteRunner.run(SuiteRunner.java:364)
at org.testng.SuiteRunnerWorker.runSuite(SuiteRunnerWorker.java:52)
at org.testng.SuiteRunnerWorker.run(SuiteRunnerWorker.java:84)
at org.testng.TestNG.runSuitesSequentially(TestNG.java:1208)
at org.testng.TestNG.runSuitesLocally(TestNG.java:1137)
at org.testng.TestNG.runSuites(TestNG.java:1049)
at org.testng.TestNG.run(TestNG.java:1017)
at org.testng.remote.AbstractRemoteTestNG.run(AbstractRemoteTestNG.java:115)
at org.testng.remote.RemoteTestNG.initAndRun(RemoteTestNG.java:251)
at org.testng.remote.RemoteTestNG.main(RemoteTestNG.java:77)
]]>
            </full-stacktrace>
          </exception> <!-- java.lang.AssertionError -->
          <reporter-output>
          </reporter-output>
        </test-method> <!-- assertAll -->
        <test-method status="SKIP" signature="tearDown()[pri:0, instance:com.qa.testcases.DummyTestClass1@4cf777e8]" name="tearDown" is-config="true" duration-ms="0" started-at="2021-03-25T07:27:39Z" finished-at="2021-03-25T07:27:39Z">
          <reporter-output>
          </reporter-output>
        </test-method> <!-- tearDown -->
      </class> <!-- com.qa.testcases.DummyTestClass1 -->
    </test> <!-- Selenium Easy Test Site Test Cases -->
  </suite> <!-- TestNgPOM Selenium Easy Test Suite -->
</testng-results>
